Workbook
Name 比分: #REF!

Sheet BO3
B1: BO3
B4: 结果输出区 | H4: 控制区 | P4: =_xlfn.DISPIMG("ID_DA4312AC85894956AA7CDE06ED97B8C4",1) -> =DISPIMG("ID_DA4312AC85894956AA7CDE06ED97B8C4",1)
B7: 主队名 | C7: vs | E7: 客队名 | H7: 队伍填写 | I7: 主队名 | J7: 客队名 | K7: 时间
B8: =I8 -> 0 | E8: =J8 -> 0
B9: =I10&"年" -> 年 | C9: =J10&"月" -> 月 | D9: =K10&"日" -> 日 | E9: =K8 -> 0 | H9: 日期填写 | I9: 年 | J9: 月 | K9: 日
B10: BO3赛制第一局：
B12: 客队禁图 | C12: =I14&" 与 "&I15 -> 与 | H12: 第一局 | P12: 使用须知 | R12: 制作 | T12: 技术指导
H13: 赛前BP | I13: 客场禁图 | J13: 主场选图 | K13: 客场选边 | R13: 养只燃宝 | T13: 弓局DeepSeek
B15: 主队选图 | C15: =J14 -> 0 | P15: 本工具旨在优化第五人格比赛中裁判记录数据的工作流程。 本工具有「BO3」和「BO5」两种模式以适应不同比赛赛制下的需求，使用者可以在右下角导航栏处自由切换。 使用时，需要在控制区的白色空格里进行填写，结果会在左侧的结果输出区同步，其中，大小比分合计、赛果，和全局BP为自动生成。
H16: 上半场
B17: 客队选边 | C17: =K14 -> 0 | H17: 监管者方禁用2人
H18: 求生者方选择2人
B19: 上半场 | H19: 监管者方禁用1人
B20: =IF(K14="监管者",I8,IF(K14="求生者",J8,""))&"求生者" -> 求生者 | C20: vs | E20: =IF(K14="监管者",J8,IF(K14="求生者",I8,""))&"监管者" -> 监管者 | H20: 求生者方选择1人
B21: 当前全局BP已禁用0人 | H21: 监管者方禁用1人
B22: 监管者方禁用2人 | D22: =J17 -> 0 | E22: =K17 -> 0 | H22: 求生者方选择1人
B23: 求生者方选择2人 | D23: =J18 -> 0 | E23: =K18 -> 0 | H23: 监管者方选择1人
B24: 监管者方禁用1人 | D24: =J19 -> 0 | H24: 本局结果
B25: 求生者方选择1人 | D25: =J20 -> 0 | H25: 下半场
B26: 监管者方禁用1人 | D26: =J21 -> 0 | H26: 监管者方禁用2人
B27: 求生者方选择1人 | D27: =J22 -> 0 | H27: 求生者方选择1人
B28: 监管者方选择1人 | D28: =J23 -> 0 | H28: 监管者方禁用1人
B29: 小比分（主：客） | D29: =BO3计算表!K8 | E29: =BO3计算表!L8 | H29: 求生者方选择1人
B30: 下半场 | H30: 监管者方禁用1人 | P30: 比分 计算规则 | R30: 依据
B31: =IF(K14="监管者",J8,IF(K14="求生者",I8,""))&"求生者" -> 求生者 | C31: vs | E31: =IF(K14="监管者",I8,IF(K14="求生者",J8,""))&"监管者" -> 监管者 | H31: 求生者方选择1人 | R31: 第五人格2025年 IVL赛事规则
B32: 当前全局BP已禁用0人 | H32: 监管者方选择1人
B33: 监管者方禁用2人 | D33: =J26 -> 0 | E33: =K26 -> 0 | H33: 本局结果 | P33: 大比分计算规则
B34: 求生者方选择1人 | D34: =J27 -> 0 | E34: =K27 -> 0 | P34: 当某队该局的小比分存在优势时，则小比分优势的队伍得1分大比分，另一队不得大比分 若某局双方小比分相等，则双方各得1分大比分
B35: 监管者方禁用1人 | D35: =J28 -> 0
B36: 求生者方选择1人 | D36: =J29 -> 0
B37: 监管者方禁用1人 | D37: =J30 -> 0
B38: 求生者方选择1人 | D38: =J31 -> 0
B39: 监管者方选择1人 | D39: =J32 -> 0 | P39: 小比分计算规则
B40: 小比分（主：客） | D40: =BO3计算表!K9 | E40: =BO3计算表!L9 | P40: 小比分为上下半场独立计算后汇总，与两支队伍求生者的逃脱数量有直接关系，具体如下：
B41: 本局大比分 | D41: =IFERROR(IF(BO3计算表!K8+BO3计算表!K9>BO3计算表!L8+BO3计算表!L9,"1：0",IF(BO3计算表!K8+BO3计算表!K9=BO3计算表!L8+BO3计算表!L9,"1：1","0：1")),"数据缺失") -> 数据缺失
P42: 小比分规则 | S42: 求生者 | T42: 监管者
B43: 小比分合计 | D43: =IFERROR((BO3计算表!K8+BO3计算表!K9)&"："&(BO3计算表!L8+BO3计算表!L9),"数据缺失") -> 数据缺失
P45: 逃脱人数 | R45: 四跑 | S45: 5 | T45: 0
R46: 三跑 | S46: 3 | T46: 1
R47: 平局 | S47: 2 | T47: 2
...

Sheet BO5
B1: [BO5]
B4: 结果输出区 | H4: 控制区 | P4: =_xlfn.DISPIMG("ID_DA4312AC85894956AA7CDE06ED97B8C4",1) -> =DISPIMG("ID_DA4312AC85894956AA7CDE06ED97B8C4",1)
B7: 主队名 | C7: vs | E7: 客队名 | H7: 队伍填写 | I7: 主队名 | J7: 客队名 | K7: 时间
B9: =I10&"年" -> 年 | C9: =J10&"月" -> 月 | D9: =K10&"日" -> 日 | E9: =K8 -> 0 | H9: 日期填写 | I9: 年 | J9: 月 | K9: 日
B10: BO5赛制第一局：
B12: 客队禁图 | C12: =I14&" 与 "&I15 -> 与 | H12: 第一局 | P12: 使用须知 | R12: 制作 | T12: 技术指导
H13: 赛前BP | I13: 客场禁图 | J13: 主场选图 | K13: 客场选边 | R13: 养只燃宝 | T13: 弓局DeepSeek
B15: 主队选图 | C15: =J14 -> 0 | P15: 本工具旨在优化第五人格比赛中裁判记录数据的工作流程。 本工具有「BO3」和「BO5」两种模式以适应不同比赛赛制下的需求，使用者可以在右下角导航栏处自由切换。 使用时，需要在控制区的白色空格里进行填写，结果会在左侧的结果输出区同步，其中，大小比分合计、赛果，和全局BP为自动生成。
H16: 上半场
B17: 客队选边 | C17: =K14 -> 0 | H17: 监管者方禁用2人
H18: 求生者方选择2人
B19: 上半场 | H19: 监管者方禁用1人
B20: =IF(K14="监管者",I8,IF(K14="求生者",J8,""))&"求生者" -> 求生者 | C20: vs | E20: =IF(K14="监管者",J8,IF(K14="求生者",I8,""))&"监管者" -> 监管者 | H20: 求生者方选择1人
B21: 当前全局BP已禁用0人 | H21: 监管者方禁用1人
B22: 监管者方禁用2人 | D22: =J17 -> 0 | E22: =K17 -> 0 | H22: 求生者方选择1人
B23: 求生者方选择2人 | D23: =J18 -> 0 | E23: =K18 -> 0 | H23: 监管者方选择1人
B24: 监管者方禁用1人 | D24: =J19 -> 0 | H24: 本局结果
B25: 求生者方选择1人 | D25: =J20 -> 0 | H25: 下半场
B26: 监管者方禁用1人 | D26: =J21 -> 0 | H26: 监管者方禁用2人
B27: 求生者方选择1人 | D27: =J22 -> 0 | H27: 求生者方选择1人
B28: 监管者方选择1人 | D28: =J23 -> 0 | H28: 监管者方禁用1人
B29: 小比分（主：客） | D29: =BO5计算表!K8 | E29: =BO5计算表!L8 | H29: 求生者方选择1人
B30: 下半场 | H30: 监管者方禁用1人 | P30: 比分 计算规则 | R30: 依据
B31: =IF(K14="监管者",J8,IF(K14="求生者",I8,""))&"求生者" -> 求生者 | C31: vs | E31: =IF(K14="监管者",I8,IF(K14="求生者",J8,""))&"监管者" -> 监管者 | H31: 求生者方选择1人 | R31: 第五人格2025年 IVL赛事规则
B32: 当前全局BP已禁用0人 | H32: 监管者方选择1人
B33: 监管者方禁用2人 | D33: =J26 -> 0 | E33: =K26 -> 0 | H33: 本局结果 | P33: 大比分计算规则
B34: 求生者方选择1人 | D34: =J27 -> 0 | E34: =K27 -> 0 | P34: 当某队该局的小比分存在优势时，则小比分优势的队伍得1分大比分，另一队不得大比分 若某局双方小比分相等，则双方各得1分大比分
B35: 监管者方禁用1人 | D35: =J28 -> 0
B36: 求生者方选择1人 | D36: =J29 -> 0
B37: 监管者方禁用1人 | D37: =J30 -> 0
B38: 求生者方选择1人 | D38: =J31 -> 0
B39: 监管者方选择1人 | D39: =J32 -> 0 | P39: 小比分计算规则
B40: 小比分（主：客） | D40: =BO5计算表!K9 | E40: =BO5计算表!L9 | P40: 小比分为上下半场独立计算后汇总，与两支队伍求生者的逃脱数量有直接关系，具体如下：
B41: 本局大比分 | D41: =IF(BO5计算表!M8="","数据缺失",BO5计算表!M8&"："&BO5计算表!N8) -> 数据缺失
P42: 小比分规则 | S42: 求生者 | T42: 监管者
B43: 小比分合计 | D43: =IFERROR((BO5计算表!K8+BO5计算表!K9)&"："&(BO5计算表!L8+BO5计算表!L9),"数据缺失") -> 数据缺失
P45: 逃脱人数 | R45: 四跑 | S45: 5 | T45: 0
R46: 三跑 | S46: 3 | T46: 1
R47: 平局 | S47: 2 | T47: 2
B48: BO5赛制第二局： | H48: 第二局 | R48: 三抓 | S48: 1 | T48: 3
...

Sheet 更新日志
B2: 更新日志
B7: 2026年2月15日 V4.0更新日志 新增了BO5赛制表格 新增了比分计算规则的提示 修复了一大堆已知bug 新增了一大堆石山代码和bug 适配了比赛规则中的特殊结束规则 优化了UI表现
B19: 2026年9月19日 V4.1更新日志 修复了BO3表格的一大堆已知bug 新增了一大堆石山代码和bug 新增了BO3表格中部分单元格的内容有效性审查 优化了BO3表格中部分单元格的未写入数据时的提示词
B31: 2026年9月19日 V4.2更新日志 重构了BO3表格和BO5表格的函数，删除了一大堆石山代码 新增了一些石山代码和bug 修复了BO3表格中，第一局客场方缺少一张地图禁用位置的问题

Sheet BO3计算表
B2: BO3计算表
A7: 对局 | B7: 半场 | C7: 主队 | D7: 客队 | E7: 主场持边 | F7: 监管者方队伍 | G7: 求生者方队伍 | H7: 本局结果 | I7: 监管得分 | J7: 求生得分 | K7: 主小比分 | L7: 客小比分 | M7: 主大比分 | N7: 客大比分 | O7: 备注
A8: 1 | B8: 上 | C8: ='BO3'!I8 -> 0 | D8: ='BO3'!J8 -> 0 | E8: =IF('BO3'!K14="监管者","求生者","监管者") -> 监管者 | F8: =IF(E8="监管者",C8,D8) -> 0 | G8: =IF(E8="监管者",D8,C8) -> 0 | H8: ='BO3'!J24 -> 0 | I8: {=IFERROR(INDEX(tblRules[监管者得分],MATCH(H8,tblRules[结果],0)),"")} | J8: {=IFERROR(INDEX(tblRules[求生者得分],MATCH(H8,tblRules[结果],0)),"")} | K8: =IF(OR($H8="",$F8=""),"",IF($F8=$C8,$I8,$J8)) | L8: =IF(OR($H8="",$F8=""),"",IF($F8=$D8,$I8,$J8)) | M8: =IF(OR($H8="",$F8="",$K8="",$L8=""),"",IF($K8>$L8,1,IF($K8=$L8,1,0))) | N8: =IF(OR($H8="",$F8="",$K8="",$L8=""),"",IF($L8>$K8,1,IF($K8=$L8,1,0)))
B9: 下 | C9: ='BO3'!I8 -> 0 | D9: ='BO3'!J8 -> 0 | E9: =IF('BO3'!K14="监管者","监管者","求生者") -> 求生者 | F9: =IF(E8="监管者",D8,C8) -> 0 | G9: =IF(E8="监管者",C8,D8) -> 0 | H9: ='BO3'!J33 -> 0 | I9: {=IFERROR(INDEX(tblRules[监管者得分],MATCH(H9,tblRules[结果],0)),"")} | J9: {=IFERROR(INDEX(tblRules[求生者得分],MATCH(H9,tblRules[结果],0)),"")} | K9: =IF(OR($H9="",$F9=""),"",IF($F9=$C9,I9,J9)) | L9: =IF(OR($H9="",$F9=""),"",IF($F9=$D9,I9,J9)) | M9: =IF(OR($H9="",$F9="",$K9="",$L9=""),"",IF($K9>$L9,1,IF($K9=$L9,1,0))) | N9: =IF(OR($H9="",$F9="",$K9="",$L9=""),"",IF($L9>$K9,1,IF($K9=$L9,1,0)))
A10: 2 | B10: 上 | C10: ='BO3'!I8 -> 0 | D10: ='BO3'!J8 -> 0 | E10: =IF('BO3'!K50="监管者","监管者","求生者") -> 求生者 | F10: =IF(E10="监管者",C10,D10) -> 0 | G10: =IF(E10="求生者",C10,D10) -> 0 | H10: ='BO3'!J60 -> 0 | I10: {=IFERROR(INDEX(tblRules[监管者得分],MATCH(H10,tblRules[结果],0)),"")} | J10: {=IFERROR(INDEX(tblRules[求生者得分],MATCH(H10,tblRules[结果],0)),"")} | K10: =IF(OR($H10="",$F10=""),"",IF($F10=$C10,$I10,$J10)) | L10: =IF(OR($H10="",$F10=""),"",IF($F10=$D10,$I10,$J10)) | M10: =IF(OR($H10="",$F10="",$K10="",$L10=""),"",IF($K10>$L10,1,IF($K10=$L10,1,0))) | N10: =IF(OR($H10="",$F10="",$K10="",$L10=""),"",IF($L10>$K10,1,IF($K10=$L10,1,0)))
B11: 下 | C11: ='BO3'!I8 -> 0 | D11: ='BO3'!J8 -> 0 | E11: =IF('BO3'!K50="监管者","求生者","监管者") -> 监管者 | F11: =IF(E11="监管者",C11,D11) -> 0 | G11: =IF(E11="求生者",C11,D11) -> 0 | H11: ='BO3'!J79 -> 0 | I11: {=IFERROR(INDEX(tblRules[监管者得分],MATCH(H11,tblRules[结果],0)),"")} | J11: {=IFERROR(INDEX(tblRules[求生者得分],MATCH(H11,tblRules[结果],0)),"")} | K11: =IF(OR($H11="",$F11=""),"",IF($F11=$C11,I11,J11)) | L11: =IF(OR($H11="",$F11=""),"",IF($F11=$D11,$I11,$J11)) | M11: =IF(OR($H11="",$F11="",$K11="",$L11=""),"",IF($K11>$L11,1,IF($K11=$L11,1,0))) | N11: =IF(OR($H11="",$F11="",$K11="",$L11=""),"",IF($L11>$K11,1,IF($K11=$L11,1,0)))
A12: 3 | B12: 上 | C12: ='BO3'!I8 -> 0 | D12: ='BO3'!J8 -> 0 | E12: =IF('BO3'!K101="监管者","求生者","监管者") -> 监管者 | F12: =IF(E12="监管者",C12,D12) -> 0 | G12: =IF(E12="求生者",C12,D12) -> 0 | H12: ='BO3'!J111 -> 0 | I12: {=IFERROR(INDEX(tblRules[监管者得分],MATCH(H12,tblRules[结果],0)),"")} | J12: {=IFERROR(INDEX(tblRules[求生者得分],MATCH(H12,tblRules[结果],0)),"")} | K12: =IF(OR($H12="",$F12=""),"",IF($F12=$C12,$I12,$J12)) | L12: =IF(OR($H12="",$F12=""),"",IF($F12=$D12,$I12,$J12)) | M12: =IF(OR($H12="",$F12="",$K12="",$L12=""),"",IF($K12>$L12,1,IF($K12=$L12,1,0))) | N12: =IF(OR($H12="",$F12="",$K12="",$L12=""),"",IF($L12>$K12,1,IF($K12=$L12,1,0)))
B13: 下 | C13: ='BO3'!I8 -> 0 | D13: ='BO3'!J8 -> 0 | E13: =IF('BO3'!K101="监管者","监管者","求生者") -> 求生者 | F13: =IF(E13="监管者",C13,D13) -> 0 | G13: =IF(E13="求生者",C13,D13) -> 0 | H13: ='BO3'!J130 -> 0 | I13: {=IFERROR(INDEX(tblRules[监管者得分],MATCH(H13,tblRules[结果],0)),"")} | J13: {=IFERROR(INDEX(tblRules[求生者得分],MATCH(H13,tblRules[结果],0)),"")} | K13: =IF(OR($H13="",$F13=""),"",IF($F13=$C13,$I13,$J13)) | L13: =IF(OR($H13="",$F13=""),"",IF($F13=$D13,$I13,$J13)) | M13: =IF(OR($H13="",$F13="",$K13="",$L13=""),"",IF($K13>$L13,1,IF($K13=$L13,1,0))) | N13: =IF(OR($H13="",$F13="",$K13="",$L13=""),"",IF($L13>$K13,1,IF($K13=$L13,1,0)))
A14: 加赛 | B14: 上 | C14: ='BO3'!I8 -> 0 | D14: ='BO3'!J8 -> 0 | E14: =IF('BO3'!K153="监管者","监管者","求生者") -> 求生者 | F14: =IF(E14="监管者",C14,D14) -> 0 | G14: =IF(E14="求生者",C14,D14) -> 0 | H14: ='BO3'!J163 -> 0 | I14: {=IFERROR(INDEX(tblRules[监管者得分],MATCH(H14,tblRules[结果],0)),"")} | J14: {=IFERROR(INDEX(tblRules[求生者得分],MATCH(H14,tblRules[结果],0)),"")} | K14: =IF(OR($H14="",$F14=""),"",IF($F14=$C14,$I14,$J14)) | L14: =IF(OR($H14="",$F14=""),"",IF($F14=$D14,$I14,$J14)) | M14: =IF(OR($H14="",$F14="",$K14="",$L14=""),"",IF($K14>$L14,1,IF($K14=$L14,1,0))) | N14: =IF(OR($H14="",$F14="",$K14="",$L14=""),"",IF($L14>$K14,1,IF($K14=$L14,1,0)))
B15: 下 | C15: ='BO3'!I8 -> 0 | D15: ='BO3'!J8 -> 0 | E15: =IF('BO3'!K153="监管者","求生者","监管者") -> 监管者 | F15: =IF(E15="监管者",C15,D15) -> 0 | G15: =IF(E15="求生者",C15,D15) -> 0 | H15: ='BO3'!J185 -> 0 | I15: {=IFERROR(INDEX(tblRules[监管者得分],MATCH(H15,tblRules[结果],0)),"")} | J15: {=IFERROR(INDEX(tblRules[求生者得分],MATCH(H15,tblRules[结果],0)),"")} | K15: =IF(OR($H15="",$F15=""),"",IF($F15=$C15,$I15,$J15)) | L15: =IF(OR($H15="",$F15=""),"",IF($F15=$D15,$I15,$J15)) | M15: =IF(OR($H15="",$F15="",$K15="",$L15=""),"",IF($K15>$L15,1,IF($K15=$L15,1,0))) | N15: =IF(OR($H15="",$F15="",$K15="",$L15=""),"",IF($L15>$K15,1,IF($K15=$L15,1,0)))

Sheet 得分规则
A1: 结果 | B1: 求生者得分 | C1: 监管者得分
A2: 四跑 | B2: 5 | C2: 0
A3: 三跑 | B3: 3 | C3: 1
A4: 平局 | B4: 2 | C4: 2
A5: 三抓 | B5: 1 | C5: 3
A6: 四抓 | B6: 0 | C6: 5

Sheet BO5计算表
B2: BO5计算表
A7: 对局 | B7: 半场 | C7: 主队 | D7: 客队 | E7: 主队持边 | F7: 监管者方队伍 | G7: 求生者方队伍 | H7: 本局结果 | I7: 监管得分 | J7: 求生得分 | K7: 主小比分 | L7: 客小比分 | M7: 每局主队大比分 | N7: 每局客队大比分 | O7: 主累计大比分 | P7: 客累计大比分
A8: 1 | B8: 上 | C8: ='BO5'!$I$8 -> 0 | D8: ='BO5'!J8 -> 0 | E8: =IF('BO5'!$K$14="监管者","求生者","监管者") -> 监管者 | F8: =IF(E8="监管者",C8,D8) -> 0 | G8: =IF(E8="监管者",D8,C8) -> 0 | H8: ='BO5'!J24 -> 0 | I8: =IF($H8="","",IF($H8="四跑",0,IF($H8="三跑",1,IF($H8="平局",2,IF($H8="三抓",3,IF($H8="四抓",5,"")))))) | J8: =IF($H8="","",IF($H8="四跑",5,IF($H8="三跑",3,IF($H8="平局",2,IF($H8="三抓",1,IF($H8="四抓",0,"")))))) | K8: =IF(OR($H8="",$F8=""),"",IF($F8=$C8,$I8,$J8)) | L8: =IF(OR($H8="",$F8=""),"",IF($F8=$D8,$I8,$J8)) | M8: =IF(OR($K8="",$L8="",$K9="",$L9=""),"",IF($K8+$K9>$L8+$L9,1,IF($K8+$K9=$L8+$L9,1,0))) | N8: =IF(OR($K8="",$L8="",$K9="",$L9=""),"",IF($L8+$L9>$K8+$K9,1,IF($K8+$K9=$L8+$L9,1,0))) | O8: =IF(M8="","",SUM($M$8:M8)) | P8: =IF(N8="","",SUM($N$8:N8))
B9: 下 | C9: ='BO5'!$I$8 -> 0 | D9: ='BO5'!$J$8 -> 0 | E9: =IF('BO5'!$K$14="监管者","监管者","求生者") -> 求生者 | F9: =IF(E9="监管者",C9,D9) -> 0 | G9: =IF(E9="监管者",D9,C9) -> 0 | H9: ='BO5'!J33 -> 0 | I9: =IF($H9="","",IF($H9="四跑",0,IF($H9="三跑",1,IF($H9="平局",2,IF($H9="三抓",3,IF($H9="四抓",5,"")))))) | J9: =IF($H9="","",IF($H9="四跑",5,IF($H9="三跑",3,IF($H9="平局",2,IF($H9="三抓",1,IF($H9="四抓",0,"")))))) | K9: =IF(OR($H9="",$F9=""),"",IF($F9=$C9,$I9,$J9)) | L9: =IF(OR($H9="",$F9=""),"",IF($F9=$D9,$I9,$J9))
A10: 2 | B10: 上 | C10: ='BO5'!$I$8 -> 0 | D10: ='BO5'!$J$8 -> 0 | E10: =IF('BO5'!$K$50="监管者","监管者","求生者") -> 求生者 | F10: =IF(E10="监管者",C10,D10) -> 0 | G10: =IF(E10="监管者",D10,C10) -> 0 | H10: ='BO5'!J60 -> 0 | I10: =IF($H10="","",IF($H10="四跑",0,IF($H10="三跑",1,IF($H10="平局",2,IF($H10="三抓",3,IF($H10="四抓",5,"")))))) | J10: =IF($H10="","",IF($H10="四跑",5,IF($H10="三跑",3,IF($H10="平局",2,IF($H10="三抓",1,IF($H10="四抓",0,"")))))) | K10: =IF(OR($H10="",$F10=""),"",IF($F10=$C10,$I10,$J10)) | L10: =IF(OR($H10="",$F10=""),"",IF($F10=$D10,$I10,$J10)) | M10: =IF(OR($K10="",$L10="",$K11="",$L11=""),"",IF($K10+$K11>$L10+$L11,1,IF($K10+$K11=$L10+$L11,1,0))) | N10: =IF(OR($K10="",$L10="",$K11="",$L11=""),"",IF($L10+$L11>$K10+$K11,1,IF($K10+$K11=$L10+$L11,1,0))) | O10: =IF(M10="","",SUM($M$8:M10)) | P10: =IF(N10="","",SUM($N$8:N10))
B11: 下 | C11: ='BO5'!$I$8 -> 0 | D11: ='BO5'!$J$8 -> 0 | E11: =IF('BO5'!$K$50="监管者","求生者","监管者") -> 监管者 | F11: =IF(E11="监管者",C11,D11) -> 0 | G11: =IF(E11="监管者",D11,C11) -> 0 | H11: ='BO5'!J79 -> 0 | I11: =IF($H11="","",IF($H11="四跑",0,IF($H11="三跑",1,IF($H11="平局",2,IF($H11="三抓",3,IF($H11="四抓",5,"")))))) | J11: =IF($H11="","",IF($H11="四跑",5,IF($H11="三跑",3,IF($H11="平局",2,IF($H11="三抓",1,IF($H11="四抓",0,"")))))) | K11: =IF(OR($H11="",$F11=""),"",IF($F11=$C11,$I11,$J11)) | L11: =IF(OR($H11="",$F11=""),"",IF($F11=$D11,$I11,$J11))
A12: 3 | B12: 上 | C12: ='BO5'!$I$8 -> 0 | D12: ='BO5'!$J$8 -> 0 | E12: =IF('BO5'!$K$94="监管者","求生者","监管者") -> 监管者 | F12: =IF(E12="监管者",C12,D12) -> 0 | G12: =IF(E12="监管者",D12,C12) -> 0 | H12: ='BO5'!J104 -> 0 | I12: =IF($H12="","",IF($H12="四跑",0,IF($H12="三跑",1,IF($H12="平局",2,IF($H12="三抓",3,IF($H12="四抓",5,"")))))) | J12: =IF($H12="","",IF($H12="四跑",5,IF($H12="三跑",3,IF($H12="平局",2,IF($H12="三抓",1,IF($H12="四抓",0,"")))))) | K12: =IF(OR($H12="",$F12=""),"",IF($F12=$C12,$I12,$J12)) | L12: =IF(OR($H12="",$F12=""),"",IF($F12=$D12,$I12,$J12)) | M12: =IF(OR($K12="",$L12="",$K13="",$L13=""),"",IF($K12+$K13>$L12+$L13,1,IF($K12+$K13=$L12+$L13,1,0))) | N12: =IF(OR($K12="",$L12="",$K13="",$L13=""),"",IF($L12+$L13>$K12+$K13,1,IF($K12+$K13=$L12+$L13,1,0))) | O12: =IF(M12="","",SUM($M$8:M12)) | P12: =IF(N12="","",SUM($N$8:N12))
B13: 下 | C13: ='BO5'!$I$8 -> 0 | D13: ='BO5'!$J$8 -> 0 | E13: =IF('BO5'!$K$94="监管者","监管者","求生者") -> 求生者 | F13: =IF(E13="监管者",C13,D13) -> 0 | G13: =IF(E13="监管者",D13,C13) -> 0 | H13: ='BO5'!J123 -> 0 | I13: =IF($H13="","",IF($H13="四跑",0,IF($H13="三跑",1,IF($H13="平局",2,IF($H13="三抓",3,IF($H13="四抓",5,"")))))) | J13: =IF($H13="","",IF($H13="四跑",5,IF($H13="三跑",3,IF($H13="平局",2,IF($H13="三抓",1,IF($H13="四抓",0,"")))))) | K13: =IF(OR($H13="",$F13=""),"",IF($F13=$C13,$I13,$J13)) | L13: =IF(OR($H13="",$F13=""),"",IF($F13=$D13,$I13,$J13))
A14: 4 | B14: 上 | C14: ='BO5'!$I$8 -> 0 | D14: ='BO5'!$J$8 -> 0 | E14: =IF('BO5'!$K$146="监管者","监管者","求生者") -> 求生者 | F14: =IF(E14="监管者",C14,D14) -> 0 | G14: =IF(E14="监管者",D14,C14) -> 0 | H14: ='BO5'!J156 -> 0 | I14: =IF($H14="","",IF($H14="四跑",0,IF($H14="三跑",1,IF($H14="平局",2,IF($H14="三抓",3,IF($H14="四抓",5,"")))))) | J14: =IF($H14="","",IF($H14="四跑",5,IF($H14="三跑",3,IF($H14="平局",2,IF($H14="三抓",1,IF($H14="四抓",0,"")))))) | K14: =IF(OR($H14="",$F14=""),"",IF($F14=$C14,$I14,$J14)) | L14: =IF(OR($H14="",$F14=""),"",IF($F14=$D14,$I14,$J14)) | M14: =IF(OR($K14="",$L14="",$K15="",$L15=""),"",IF($K14+$K15>$L14+$L15,1,IF($K14+$K15=$L14+$L15,1,0))) | N14: =IF(OR($K14="",$L14="",$K15="",$L15=""),"",IF($L14+$L15>$K14+$K15,1,IF($K14+$K15=$L14+$L15,1,0))) | O14: =IF(M14="","",SUM($M$8:M14)) | P14: =IF(N14="","",SUM($N$8:N14))
B15: 下 | C15: ='BO5'!$I$8 -> 0 | D15: ='BO5'!$J$8 -> 0 | E15: =IF('BO5'!$K$146="监管者","求生者","监管者") -> 监管者 | F15: =IF(E15="监管者",C15,D15) -> 0 | G15: =IF(E15="监管者",D15,C15) -> 0 | H15: ='BO5'!J178 -> 0 | I15: =IF($H15="","",IF($H15="四跑",0,IF($H15="三跑",1,IF($H15="平局",2,IF($H15="三抓",3,IF($H15="四抓",5,"")))))) | J15: =IF($H15="","",IF($H15="四跑",5,IF($H15="三跑",3,IF($H15="平局",2,IF($H15="三抓",1,IF($H15="四抓",0,"")))))) | K15: =IF(OR($H15="",$F15=""),"",IF($F15=$C15,$I15,$J15)) | L15: =IF(OR($H15="",$F15=""),"",IF($F15=$D15,$I15,$J15))
A16: 5 | B16: 上 | C16: ='BO5'!$I$8 -> 0 | D16: ='BO5'!$J$8 -> 0 | E16: =IF('BO5'!$K$197="监管者","求生者","监管者") -> 监管者 | F16: =IF(E16="监管者",C16,D16) -> 0 | G16: =IF(E16="监管者",D16,C16) -> 0 | H16: ='BO5'!J207 -> 0 | I16: =IF($H16="","",IF($H16="四跑",0,IF($H16="三跑",1,IF($H16="平局",2,IF($H16="三抓",3,IF($H16="四抓",5,"")))))) | J16: =IF($H16="","",IF($H16="四跑",5,IF($H16="三跑",3,IF($H16="平局",2,IF($H16="三抓",1,IF($H16="四抓",0,"")))))) | K16: =IF(OR($H16="",$F16=""),"",IF($F16=$C16,$I16,$J16)) | L16: =IF(OR($H16="",$F16=""),"",IF($F16=$D16,$I16,$J16)) | M16: =IF(OR($K16="",$L16="",$K17="",$L17=""),"",IF($K16+$K17>$L16+$L17,1,IF($K16+$K17=$L16+$L17,1,0))) | N16: =IF(OR($K16="",$L16="",$K17="",$L17=""),"",IF($L16+$L17>$K16+$K17,1,IF($K16+$K17=$L16+$L17,1,0))) | O16: =IF(M16="","",SUM($M$8:M16)) | P16: =IF(N16="","",SUM($N$8:N16))
B17: 下 | C17: ='BO5'!$I$8 -> 0 | D17: ='BO5'!$J$8 -> 0 | E17: =IF('BO5'!$K$197="监管者","监管者","求生者") -> 求生者 | F17: =IF(E17="监管者",C17,D17) -> 0 | G17: =IF(E17="监管者",D17,C17) -> 0 | H17: ='BO5'!J231 -> 0 | I17: =IF($H17="","",IF($H17="四跑",0,IF($H17="三跑",1,IF($H17="平局",2,IF($H17="三抓",3,IF($H17="四抓",5,"")))))) | J17: =IF($H17="","",IF($H17="四跑",5,IF($H17="三跑",3,IF($H17="平局",2,IF($H17="三抓",1,IF($H17="四抓",0,"")))))) | K17: =IF(OR($H17="",$F17=""),"",IF($F17=$C17,$I17,$J17)) | L17: =IF(OR($H17="",$F17=""),"",IF($F17=$D17,$I17,$J17))
A18: 加赛 | B18: 上 | C18: ='BO5'!$I$8 -> 0 | D18: ='BO5'!$J$8 -> 0 | E18: =IF('BO5'!K197="监管者","求生者","监管者") -> 监管者 | F18: =IF(E18="监管者",C18,D18) -> 0 | G18: =IF(E18="监管者",D18,C18) -> 0 | H18: ='BO5'!J267 -> 0 | I18: =IF($H18="","",IF($H18="四跑",0,IF($H18="三跑",1,IF($H18="平局",2,IF($H18="三抓",3,IF($H18="四抓",5,"")))))) | J18: =IF($H18="","",IF($H18="四跑",5,IF($H18="三跑",3,IF($H18="平局",2,IF($H18="三抓",1,IF($H18="四抓",0,"")))))) | K18: =IF(OR($H18="",$F18=""),"",IF($F18=$C18,$I18,$J18)) | L18: =IF(OR($H18="",$F18=""),"",IF($F18=$D18,$I18,$J18)) | M18: =IF(OR($K18="",$L18="",$K19="",$L19=""),"",IF($K18+$K19>$L18+$L19,1,IF($K18+$K19=$L18+$L19,1,0))) | N18: =IF(OR($K18="",$L18="",$K19="",$L19=""),"",IF($L18+$L19>$K18+$K19,1,IF($K18+$K19=$L18+$L19,1,0))) | O18: =IF(M18="","",SUM($M$8:M18)) | P18: =IF(N18="","",SUM($N$8:N18))
B19: 下 | C19: ='BO5'!$I$8 -> 0 | D19: ='BO5'!$J$8 -> 0 | E19: =IF('BO5'!K197="监管者","监管者","求生者") -> 求生者 | F19: =IF(E19="监管者",C19,D19) -> 0 | G19: =IF(E19="监管者",D19,C19) -> 0 | H19: ='BO5'!J290 -> 0 | I19: =IF($H19="","",IF($H19="四跑",0,IF($H19="三跑",1,IF($H19="平局",2,IF($H19="三抓",3,IF($H19="四抓",5,"")))))) | J19: =IF($H19="","",IF($H19="四跑",5,IF($H19="三跑",3,IF($H19="平局",2,IF($H19="三抓",1,IF($H19="四抓",0,"")))))) | K19: =IF(OR($H19="",$F19=""),"",IF($F19=$C19,J19,I19)) | L19: =IF(OR($H19="",$F19=""),"",IF($F19=$D19,J19,I19))

Sheet WpsReserved_CellImgList
